<?xml version="1.0" ?>
<!-- =================================================================================== -->
<!-- |    This document was autogenerated by xacro from 2F85_BuildURDF.xacro           | -->
<!-- |    EDITING THIS FILE BY HAND IS NOT RECOMMENDED                                 | -->
<!-- =================================================================================== -->
<robot name="Robotiq_2F85">
  <!-- On the first day, Darwin created the world -->
  <!-- <link name="world"/> -->
  <!-- base -->
 <!--<joint name="world_gripper_base_joint" type="fixed">
    <origin rpy="0 1.5707963267948966 0" xyz="0 0 0"/>
    <parent link="world"/>
    <child link="gripper_base"/>
  </joint>-->
  <link name="gripper_base">
    <inertial>
      <mass value="0.5"/>
      <origin xyz="0 0 0.0075"/>
      <inertia ixx="0.284375" ixy="0" ixz="0" iyy="0.284375" iyz="0" izz="0.4"/>
    </inertial>
    <visual>
      <origin rpy="0 -1.5708 0" xyz="0 0 0"/>
      <geometry>
        <mesh filename="package://robotiq_2f_model/meshes/2f85/visual/base.obj"/>
      </geometry>
    </visual>
    <collision>
      <geometry>
        <mesh filename="package://robotiq_2f_model/meshes/2f85/collision/base.stl" scale="0.001 0.001 0.001"/>
      </geometry>
    </collision>
  </link>
  <!-- right finger -->
  <joint name="gripper_right_driver_joint" type="revolute">
    <origin rpy="0 0 0" xyz="0 0.0306011 0.054904"/>
    <parent link="gripper_base"/>
    <child link="gripper_right_driver"/>
    <axis xyz="1 0 0"/>
    <limit effort="176" lower="0.0" upper="0.8726644444444445" velocity="1.919861777777778"/>
  </joint>
  <link name="gripper_right_driver">
    <inertial>
      <mass value="0.1"/>
      <origin rpy="0 0 0" xyz="0 0.02 0"/>
      <inertia ixx="0.016666666666666666" ixy="0" ixz="0" iyy="0.006666666666666667" iyz="0" izz="0.016666666666666666"/>
    </inertial>
    <visual>
      <geometry>
        <mesh filename="package://robotiq_2f_model/meshes/2f85/visual/driver.obj" scale="0.001 0.001 0.001"/>
      </geometry>
    </visual>
    <collision>
      <geometry>
        <mesh filename="package://robotiq_2f_model/meshes/2f85/collision/driver.stl" scale="0.001 0.001 0.001"/>
      </geometry>
    </collision>
  </link>
  <joint name="gripper_right_coupler_joint" type="revolute">
    <origin rpy="0 0 0" xyz="0 0.0315 -0.0041"/>
    <parent link="gripper_right_driver"/>
    <child link="gripper_right_coupler"/>
    <axis xyz="1 0 0"/>
    <limit effort="176" lower="-2.9670591111111113" upper="2.9670591111111113" velocity="1.919861777777778"/>
  </joint>
  <link name="gripper_right_coupler">
    <inertial>
      <mass value="0.1"/>
      <origin rpy="-1.7 0 0" xyz="0 0.0 0.025"/>
      <inertia ixx="0.038541666666666675" ixy="0" ixz="0" iyy="0.010833333333333334" iyz="0" izz="0.04270833333333334"/>
    </inertial>
    <visual>
      <geometry>
        <mesh filename="package://robotiq_2f_model/meshes/2f85/visual/coupler.obj" scale="0.001 0.001 0.001"/>
      </geometry>
    </visual>
    <collision>
      <geometry>
        <mesh filename="package://robotiq_2f_model/meshes/2f85/collision/coupler.stl" scale="0.001 0.001 0.001"/>
      </geometry>
    </collision>
  </link>
  <joint name="gripper_right_follower_joint" type="revolute">
    <origin rpy="0 0 0" xyz="0 0.0061 0.0471"/>
    <parent link="gripper_right_coupler"/>
    <child link="gripper_right_follower"/>
    <axis xyz="1 0 0"/>
    <limit effort="176" lower="-2.9670591111111113" upper="2.9670591111111113" velocity="1.919861777777778"/>
  </joint>
  <link name="gripper_right_follower">
    <inertial>
      <mass value="0.1"/>
      <origin xyz="0 -0.018 0.022"/>
      <inertia ixx="0.021075" ixy="0" ixz="0" iyy="0.022533333333333336" iyz="0" izz="0.005208333333333333"/>
    </inertial>
    <visual>
      <geometry>
        <mesh filename="package://robotiq_2f_model/meshes/2f85/visual/follower.obj" scale="0.001 0.001 0.001"/>
      </geometry>
    </visual>
    <collision>
      <geometry>
        <mesh filename="package://robotiq_2f_model/meshes/2f85/collision/follower.stl" scale="0.001 0.001 0.001"/>
      </geometry>
    </collision>
  </link>
  <joint name="gripper_right_pad_joint" type="fixed">
    <parent link="gripper_right_follower"/>
    <child link="gripper_right_pad"/>
  </joint>
  <link name="gripper_right_pad">
    <inertial>
      <mass value="0.1"/>
      <origin xyz="0 -0.022 0.031"/>
      <inertia ixx="0.011333333333333332" ixy="0" ixz="0" iyy="0.014133333333333331" iyz="0" izz="0.0038666666666666663"/>
    </inertial>
    <visual>
      <geometry>
        <mesh filename="package://robotiq_2f_model/meshes/2f85/visual/pad.obj" scale="0.001 0.001 0.001"/>
      </geometry>
    </visual>
    <collision>
      <geometry>
        <mesh filename="package://robotiq_2f_model/meshes/2f85/collision/pad.stl" scale="0.001 0.001 0.001"/>
      </geometry>
    </collision>
  </link>
  <joint name="gripper_right_spring_link_joint" type="revolute">
    <origin rpy="0 0 0" xyz="0 0.012 0.0614"/>
    <parent link="gripper_base"/>
    <child link="gripper_right_spring_link"/>
    <axis xyz="1 0 0"/>
    <limit effort="176" lower="-2.9670591111111113" upper="2.9670591111111113" velocity="1.919861777777778"/>
  </joint>
  <link name="gripper_right_spring_link">
    <inertial>
      <mass value="0.1"/>
      <origin rpy="-0.7068 0 0" xyz="0 0.018 0.018"/>
      <inertia ixx="0.038541666666666675" ixy="0" ixz="0" iyy="0.04854166666666667" iyz="0" izz="0.016666666666666666"/>
    </inertial>
    <visual>
      <geometry>
        <mesh filename="package://robotiq_2f_model/meshes/2f85/visual/spring_link.obj" scale="0.001 0.001 0.001"/>
      </geometry>
    </visual>
    <collision>
      <geometry>
        <mesh filename="package://robotiq_2f_model/meshes/2f85/collision/spring_link.stl" scale="0.001 0.001 0.001"/>
      </geometry>
    </collision>
  </link>
  <!-- left finger -->
  <joint name="gripper_left_driver_joint" type="revolute">
    <origin rpy="0 0 3.141592653589793" xyz="0 -0.0306011 0.054904"/>
    <parent link="gripper_base"/>
    <child link="gripper_left_driver"/>
    <axis xyz="1 0 0"/>
    <limit effort="176" lower="0.0" upper="0.8726644444444445" velocity="1.919861777777778"/>
  </joint>
  <link name="gripper_left_driver">
    <inertial>
      <mass value="0.1"/>
      <origin rpy="0 0 0" xyz="0 0.02 0"/>
      <inertia ixx="0.016666666666666666" ixy="0" ixz="0" iyy="0.006666666666666667" iyz="0" izz="0.016666666666666666"/>
    </inertial>
    <visual>
      <geometry>
        <mesh filename="package://robotiq_2f_model/meshes/2f85/visual/driver.obj" scale="0.001 0.001 0.001"/>
      </geometry>
    </visual>
    <collision>
      <geometry>
        <mesh filename="package://robotiq_2f_model/meshes/2f85/collision/driver.stl" scale="0.001 0.001 0.001"/>
      </geometry>
    </collision>
  </link>
  <joint name="gripper_left_coupler_joint" type="revolute">
    <origin rpy="0 0 0" xyz="0 0.0315 -0.0041"/>
    <parent link="gripper_left_driver"/>
    <child link="gripper_left_coupler"/>
    <axis xyz="1 0 0"/>
    <limit effort="176" lower="-2.9670591111111113" upper="2.9670591111111113" velocity="1.919861777777778"/>
  </joint>
  <link name="gripper_left_coupler">
    <inertial>
      <mass value="0.1"/>
      <origin rpy="-1.7 0 0" xyz="0 0.0 0.025"/>
      <inertia ixx="0.038541666666666675" ixy="0" ixz="0" iyy="0.010833333333333334" iyz="0" izz="0.04270833333333334"/>
    </inertial>
    <visual>
      <geometry>
        <mesh filename="package://robotiq_2f_model/meshes/2f85/visual/coupler.obj" scale="0.001 0.001 0.001"/>
      </geometry>
    </visual>
    <collision>
      <geometry>
        <mesh filename="package://robotiq_2f_model/meshes/2f85/collision/coupler.stl" scale="0.001 0.001 0.001"/>
      </geometry>
    </collision>
  </link>
  <joint name="gripper_left_follower_joint" type="revolute">
    <origin rpy="0 0 0" xyz="0 0.0061 0.0471"/>
    <parent link="gripper_left_coupler"/>
    <child link="gripper_left_follower"/>
    <axis xyz="1 0 0"/>
    <limit effort="176" lower="-2.9670591111111113" upper="2.9670591111111113" velocity="1.919861777777778"/>
  </joint>
  <link name="gripper_left_follower">
    <inertial>
      <mass value="0.1"/>
      <origin xyz="0 -0.018 0.022"/>
      <inertia ixx="0.021075" ixy="0" ixz="0" iyy="0.022533333333333336" iyz="0" izz="0.005208333333333333"/>
    </inertial>
    <visual>
      <geometry>
        <mesh filename="package://robotiq_2f_model/meshes/2f85/visual/follower.obj" scale="0.001 0.001 0.001"/>
      </geometry>
    </visual>
    <collision>
      <geometry>
        <mesh filename="package://robotiq_2f_model/meshes/2f85/collision/follower.stl" scale="0.001 0.001 0.001"/>
      </geometry>
    </collision>
  </link>
  <joint name="gripper_left_pad_joint" type="fixed">
    <parent link="gripper_left_follower"/>
    <child link="gripper_left_pad"/>
  </joint>
  <link name="gripper_left_pad">
    <inertial>
      <mass value="0.1"/>
      <origin xyz="0 -0.022 0.031"/>
      <inertia ixx="0.011333333333333332" ixy="0" ixz="0" iyy="0.014133333333333331" iyz="0" izz="0.0038666666666666663"/>
    </inertial>
    <visual>
      <geometry>
        <mesh filename="package://robotiq_2f_model/meshes/2f85/visual/pad.obj" scale="0.001 0.001 0.001"/>
      </geometry>
    </visual>
    <collision>
      <geometry>
        <mesh filename="package://robotiq_2f_model/meshes/2f85/collision/pad.stl" scale="0.001 0.001 0.001"/>
      </geometry>
    </collision>
  </link>
  <joint name="gripper_left_spring_link_joint" type="revolute">
    <origin rpy="0 0 3.141592653589793" xyz="0 -0.012 0.0614"/>
    <parent link="gripper_base"/>
    <child link="gripper_left_spring_link"/>
    <axis xyz="1 0 0"/>
    <limit effort="176" lower="-2.9670591111111113" upper="2.9670591111111113" velocity="1.919861777777778"/>
  </joint>
  <link name="gripper_left_spring_link">
    <inertial>
      <mass value="0.1"/>
      <origin rpy="-0.7068 0 0" xyz="0 0.018 0.018"/>
      <inertia ixx="0.038541666666666675" ixy="0" ixz="0" iyy="0.04854166666666667" iyz="0" izz="0.016666666666666666"/>
    </inertial>
    <visual>
      <geometry>
        <mesh filename="package://robotiq_2f_model/meshes/2f85/visual/spring_link.obj" scale="0.001 0.001 0.001"/>
      </geometry>
    </visual>
    <collision>
      <geometry>
        <mesh filename="package://robotiq_2f_model/meshes/2f85/collision/spring_link.stl" scale="0.001 0.001 0.001"/>
      </geometry>
    </collision>
  </link>
</robot>

