<?xml version="1.0" ?>
<!-- =================================================================================== -->
<!-- |    This document was autogenerated by xacro from UR5_2F85_BuildURDF.xacro       | -->
<!-- |    EDITING THIS FILE BY HAND IS NOT RECOMMENDED                                 | -->
<!-- =================================================================================== -->
<robot name="starsthing">
  <!-- On the first day, Darwin created the world -->
  <link name="world"/>
  <!-- <xacro:include filename="$(find ur_description)/urdf/ur.transmission.xacro" /> -->
  <!-- <xacro:include filename="$(find ur_description)/urdf/ur.gazebo.xacro" /> -->
  <!-- Attach UR5's base to the ground so it doesnt fall over -->
  <joint name="fixed" type="fixed">
    <parent link="world"/>
    <child link="base_link"/>
  </joint>
  <!-- measured from model -->
  <!--property name="shoulder_height" value="0.089159" /-->
  <!--property name="shoulder_offset" value="0.13585" /-->
  <!-- shoulder_offset - elbow_offset + wrist_1_length = 0.10915 -->
  <!--property name="upper_arm_length" value="0.42500" /-->
  <!--property name="elbow_offset" value="0.1197" /-->
  <!-- CAD measured -->
  <!--property name="forearm_length" value="0.39225" /-->
  <!--property name="wrist_1_length" value="0.093" /-->
  <!-- CAD measured -->
  <!--property name="wrist_2_length" value="0.09465" /-->
  <!-- In CAD this distance is 0.930, but in the spec it is 0.09465 -->
  <!--property name="wrist_3_length" value="0.0823" /-->
  <!-- manually measured -->
  <link name="base_link">
    <visual>
      <geometry>
        <mesh filename="package://ur5/ur_description/meshes/ur5/visual/base.dae"/>
      </geometry>
      <material name="LightGrey">
        <color rgba="0.7 0.7 0.7 1.0"/>
      </material>
    </visual>
    <collision>
      <geometry>
        <mesh filename="package://ur5/ur_description/meshes/ur5/collision/base.stl"/>
      </geometry>
    </collision>
    <inertial>
      <mass value="4.0"/>
      <origin rpy="0 0 0" xyz="0.0 0.0 0.0"/>
      <inertia ixx="0.00443333156" ixy="0.0" ixz="0.0" iyy="0.00443333156" iyz="0.0" izz="0.0072"/>
    </inertial>
  </link>
  <joint name="shoulder_pan_joint" type="revolute">
    <parent link="base_link"/>
    <child link="shoulder_link"/>
    <origin rpy="0.0 0.0 0.0" xyz="0.0 0.0 0.089159"/>
    <axis xyz="0 0 1"/>
    <limit effort="150.0" lower="-6.283185307179586" upper="6.283185307179586" velocity="3.15"/>
    <dynamics damping="0.0" friction="0.0"/>
  </joint>
  <link name="shoulder_link">
    <visual>
      <geometry>
        <mesh filename="package://ur5/ur_description/meshes/ur5/visual/shoulder.dae"/>
      </geometry>
      <material name="LightGrey">
        <color rgba="0.7 0.7 0.7 1.0"/>
      </material>
    </visual>
    <collision>
      <geometry>
        <mesh filename="package://ur5/ur_description/meshes/ur5/collision/shoulder.stl"/>
      </geometry>
    </collision>
    <inertial>
      <mass value="3.7"/>
      <origin rpy="0 0 0" xyz="0.0 0.0 0.0"/>
      <inertia ixx="0.010267495893" ixy="0.0" ixz="0.0" iyy="0.010267495893" iyz="0.0" izz="0.00666"/>
    </inertial>
  </link>
  <joint name="shoulder_lift_joint" type="revolute">
    <parent link="shoulder_link"/>
    <child link="upper_arm_link"/>
    <origin rpy="0.0 1.5707963267948966 0.0" xyz="0.0 0.13585 0.0"/>
    <axis xyz="0 1 0"/>
    <limit effort="150.0" lower="-6.283185307179586" upper="6.283185307179586" velocity="3.15"/>
    <dynamics damping="0.0" friction="0.0"/>
  </joint>
  <link name="upper_arm_link">
    <visual>
      <geometry>
        <mesh filename="package://ur5/ur_description/meshes/ur5/visual/upperarm.dae"/>
      </geometry>
      <material name="LightGrey">
        <color rgba="0.7 0.7 0.7 1.0"/>
      </material>
    </visual>
    <collision>
      <geometry>
        <mesh filename="package://ur5/ur_description/meshes/ur5/collision/upperarm.stl"/>
      </geometry>
    </collision>
    <inertial>
      <mass value="8.393"/>
      <origin rpy="0 0 0" xyz="0.0 0.0 0.28"/>
      <inertia ixx="0.22689067591036005" ixy="0.0" ixz="0.0" iyy="0.22689067591036005" iyz="0.0" izz="0.0151074"/>
    </inertial>
  </link>
  <joint name="elbow_joint" type="revolute">
    <parent link="upper_arm_link"/>
    <child link="forearm_link"/>
    <origin rpy="0.0 0.0 0.0" xyz="0.0 -0.1197 0.425"/>
    <axis xyz="0 1 0"/>
    <limit effort="150.0" lower="-6.283185307179586" upper="6.283185307179586" velocity="3.15"/>
    <dynamics damping="0.0" friction="0.0"/>
  </joint>
  <link name="forearm_link">
    <visual>
      <geometry>
        <mesh filename="package://ur5/ur_description/meshes/ur5/visual/forearm.dae"/>
      </geometry>
      <material name="LightGrey">
        <color rgba="0.7 0.7 0.7 1.0"/>
      </material>
    </visual>
    <collision>
      <geometry>
        <mesh filename="package://ur5/ur_description/meshes/ur5/collision/forearm.stl"/>
      </geometry>
    </collision>
    <inertial>
      <mass value="2.275"/>
      <origin rpy="0 0 0" xyz="0.0 0.0 0.196125"/>
      <inertia ixx="0.03121679102890359" ixy="0.0" ixz="0.0" iyy="0.03121679102890359" iyz="0.0" izz="0.004095"/>
    </inertial>
  </link>
  <joint name="wrist_1_joint" type="revolute">
    <parent link="forearm_link"/>
    <child link="wrist_1_link"/>
    <origin rpy="0.0 1.5707963267948966 0.0" xyz="0.0 0.0 0.39225"/>
    <axis xyz="0 1 0"/>
    <limit effort="28.0" lower="-6.283185307179586" upper="6.283185307179586" velocity="3.2"/>
    <dynamics damping="0.0" friction="0.0"/>
  </joint>
  <link name="wrist_1_link">
    <visual>
      <geometry>
        <mesh filename="package://ur5/ur_description/meshes/ur5/visual/wrist1.dae"/>
      </geometry>
      <material name="LightGrey">
        <color rgba="0.7 0.7 0.7 1.0"/>
      </material>
    </visual>
    <collision>
      <geometry>
        <mesh filename="package://ur5/ur_description/meshes/ur5/collision/wrist1.stl"/>
      </geometry>
    </collision>
    <inertial>
      <mass value="1.219"/>
      <origin rpy="0 0 0" xyz="0.0 0.093 0.0"/>
      <inertia ixx="0.0025598989760400002" ixy="0.0" ixz="0.0" iyy="0.0025598989760400002" iyz="0.0" izz="0.0021942"/>
    </inertial>
  </link>
  <joint name="wrist_2_joint" type="revolute">
    <parent link="wrist_1_link"/>
    <child link="wrist_2_link"/>
    <origin rpy="0.0 0.0 0.0" xyz="0.0 0.093 0.0"/>
    <axis xyz="0 0 1"/>
    <limit effort="28.0" lower="-6.283185307179586" upper="6.283185307179586" velocity="3.2"/>
    <dynamics damping="0.0" friction="0.0"/>
  </joint>
  <link name="wrist_2_link">
    <visual>
      <geometry>
        <mesh filename="package://ur5/ur_description/meshes/ur5/visual/wrist2.dae"/>
      </geometry>
      <material name="LightGrey">
        <color rgba="0.7 0.7 0.7 1.0"/>
      </material>
    </visual>
    <collision>
      <geometry>
        <mesh filename="package://ur5/ur_description/meshes/ur5/collision/wrist2.stl"/>
      </geometry>
    </collision>
    <inertial>
      <mass value="1.219"/>
      <origin rpy="0 0 0" xyz="0.0 0.0 0.09465"/>
      <inertia ixx="0.0025598989760400002" ixy="0.0" ixz="0.0" iyy="0.0025598989760400002" iyz="0.0" izz="0.0021942"/>
    </inertial>
  </link>
  <joint name="wrist_3_joint" type="revolute">
    <parent link="wrist_2_link"/>
    <child link="wrist_3_link"/>
    <origin rpy="0.0 0.0 0.0" xyz="0.0 0.0 0.09465"/>
    <axis xyz="0 1 0"/>
    <limit effort="28.0" lower="-6.283185307179586" upper="6.283185307179586" velocity="3.2"/>
    <dynamics damping="0.0" friction="0.0"/>
  </joint>
  <link name="wrist_3_link">
    <visual>
      <geometry>
        <mesh filename="package://ur5/ur_description/meshes/ur5/visual/wrist3.dae"/>
      </geometry>
      <material name="LightGrey">
        <color rgba="0.7 0.7 0.7 1.0"/>
      </material>
    </visual>
    <collision>
      <geometry>
        <mesh filename="package://ur5/ur_description/meshes/ur5/collision/wrist3.stl"/>
      </geometry>
    </collision>
    <inertial>
      <mass value="0.1879"/>
      <origin rpy="1.5707963267948966 0 0" xyz="0.0 0.06505 0.0"/>
      <inertia ixx="8.469589112163e-05" ixy="0.0" ixz="0.0" iyy="8.469589112163e-05" iyz="0.0" izz="0.0001321171875"/>
    </inertial>
  </link>
  <joint name="ee_fixed_joint" type="fixed">
    <parent link="wrist_3_link"/>
    <child link="ee_link"/>
    <origin rpy="0.0 0.0 1.5707963267948966" xyz="0.0 0.0823 0.0"/>
  </joint>
  <link name="ee_link">
    <collision>
      <geometry>
        <box size="0.01 0.01 0.01"/>
      </geometry>
      <origin rpy="0 0 0" xyz="-0.01 0 0"/>
    </collision>
  </link>
  <!-- <xacro:ur_arm_transmission prefix="${prefix}" hw_interface="${transmission_hw_interface}" /> -->
  <!-- <xacro:ur_arm_gazebo prefix="${prefix}" /> -->
  <!-- ROS base_link to UR 'Base' Coordinates transform -->
  <link name="base"/>
  <joint name="base_link-base_fixed_joint" type="fixed">
    <!-- NOTE: this rotation is only needed as long as base_link itself is
                 not corrected wrt the real robot (ie: rotated over 180
                 degrees)
      -->
    <origin rpy="0 0 -3.141592653589793" xyz="0 0 0"/>
    <parent link="base_link"/>
    <child link="base"/>
  </joint>
  <!-- Frame coincident with all-zeros TCP on UR controller -->
  <!-- <link name="${prefix}tool0"/>
    <joint name="${prefix}wrist_3_link-tool0_fixed_joint" type="fixed">
      <origin xyz="0 ${wrist_3_length} 0" rpy="${pi/-2.0} 0 0"/>
      <parent link="${prefix}wrist_3_link"/>
      <child link="${prefix}tool0"/>
    </joint> -->
  <!-- This defines a Tool Center Point
        If no visual element is present, the simulator will ignore the object.
        Therefore, we use a tiny cube with collision disabled in sim. -->
  <joint name="ee_link-tool0" type="fixed">
    <origin rpy="0 1.5707963267948966 0" xyz="0.15 0 0"/>
    <parent link="ee_link"/>
    <child link="tool0"/>
  </joint>
  <link name="tool0">
    <visual>
      <origin rpy="0 0 0" xyz="0 0 0"/>
      <geometry>
        <box size="0.001 0.001 0.001"/>
      </geometry>
    </visual>
  </link>
  <!-- base -->
  <joint name="ee_link_gripper_base_joint" type="fixed">
    <origin rpy="0 1.5707963267948966 0" xyz="0 0 0"/>
    <parent link="ee_link"/>
    <child link="gripper_base"/>
  </joint>
  <link name="gripper_base">
    <inertial>
      <mass value="0.5"/>
      <origin xyz="0 0 0.0075"/>
      <inertia ixx="0.284375" ixy="0" ixz="0" iyy="0.284375" iyz="0" izz="0.4"/>
    </inertial>
    <visual>
      <origin rpy="0 -1.5708 0" xyz="0 0 0"/>
      <geometry>
        <mesh filename="package://robotiq_2f_model/meshes/2f85/visual/base.obj"/>
      </geometry>
    </visual>
    <collision>
      <geometry>
        <mesh filename="package://robotiq_2f_model/meshes/2f85/collision/base.stl" scale="0.001 0.001 0.001"/>
      </geometry>
    </collision>
  </link>
  <!-- right finger -->
  <joint name="gripper_right_driver_joint" type="revolute">
    <origin rpy="0 0 0" xyz="0 0.0306011 0.054904"/>
    <parent link="gripper_base"/>
    <child link="gripper_right_driver"/>
    <axis xyz="1 0 0"/>
    <limit effort="176" lower="0.0" upper="0.8726644444444445" velocity="1.919861777777778"/>
  </joint>
  <link name="gripper_right_driver">
    <inertial>
      <mass value="0.1"/>
      <origin rpy="0 0 0" xyz="0 0.02 0"/>
      <inertia ixx="0.016666666666666666" ixy="0" ixz="0" iyy="0.006666666666666667" iyz="0" izz="0.016666666666666666"/>
    </inertial>
    <visual>
      <geometry>
        <mesh filename="package://robotiq_2f_model/meshes/2f85/visual/driver.obj" scale="0.001 0.001 0.001"/>
      </geometry>
    </visual>
    <collision>
      <geometry>
        <mesh filename="package://robotiq_2f_model/meshes/2f85/collision/driver.stl" scale="0.001 0.001 0.001"/>
      </geometry>
    </collision>
  </link>
  <joint name="gripper_right_coupler_joint" type="revolute">
    <origin rpy="0 0 0" xyz="0 0.0315 -0.0041"/>
    <parent link="gripper_right_driver"/>
    <child link="gripper_right_coupler"/>
    <axis xyz="1 0 0"/>
    <limit effort="176" lower="-2.9670591111111113" upper="2.9670591111111113" velocity="1.919861777777778"/>
  </joint>
  <link name="gripper_right_coupler">
    <inertial>
      <mass value="0.1"/>
      <origin rpy="-1.7 0 0" xyz="0 0.0 0.025"/>
      <inertia ixx="0.038541666666666675" ixy="0" ixz="0" iyy="0.010833333333333334" iyz="0" izz="0.04270833333333334"/>
    </inertial>
    <visual>
      <geometry>
        <mesh filename="package://robotiq_2f_model/meshes/2f85/visual/coupler.obj" scale="0.001 0.001 0.001"/>
      </geometry>
    </visual>
    <collision>
      <geometry>
        <mesh filename="package://robotiq_2f_model/meshes/2f85/collision/coupler.stl" scale="0.001 0.001 0.001"/>
      </geometry>
    </collision>
  </link>
  <joint name="gripper_right_follower_joint" type="revolute">
    <origin rpy="0 0 0" xyz="0 0.0061 0.0471"/>
    <parent link="gripper_right_coupler"/>
    <child link="gripper_right_follower"/>
    <axis xyz="1 0 0"/>
    <limit effort="176" lower="-2.9670591111111113" upper="2.9670591111111113" velocity="1.919861777777778"/>
  </joint>
  <link name="gripper_right_follower">
    <inertial>
      <mass value="0.1"/>
      <origin xyz="0 -0.018 0.022"/>
      <inertia ixx="0.021075" ixy="0" ixz="0" iyy="0.022533333333333336" iyz="0" izz="0.005208333333333333"/>
    </inertial>
    <visual>
      <geometry>
        <mesh filename="package://robotiq_2f_model/meshes/2f85/visual/follower.obj" scale="0.001 0.001 0.001"/>
      </geometry>
    </visual>
    <collision>
      <geometry>
        <mesh filename="package://robotiq_2f_model/meshes/2f85/collision/follower.stl" scale="0.001 0.001 0.001"/>
      </geometry>
    </collision>
  </link>
  <joint name="gripper_right_pad_joint" type="fixed">
    <parent link="gripper_right_follower"/>
    <child link="gripper_right_pad"/>
  </joint>
  <link name="gripper_right_pad">
    <inertial>
      <mass value="0.1"/>
      <origin xyz="0 -0.022 0.031"/>
      <inertia ixx="0.011333333333333332" ixy="0" ixz="0" iyy="0.014133333333333331" iyz="0" izz="0.0038666666666666663"/>
    </inertial>
    <visual>
      <geometry>
        <mesh filename="package://robotiq_2f_model/meshes/2f85/visual/pad.obj" scale="0.001 0.001 0.001"/>
      </geometry>
    </visual>
    <collision>
      <geometry>
        <mesh filename="package://robotiq_2f_model/meshes/2f85/collision/pad.stl" scale="0.001 0.001 0.001"/>
      </geometry>
    </collision>
  </link>
  <joint name="gripper_right_spring_link_joint" type="revolute">
    <origin rpy="0 0 0" xyz="0 0.012 0.0614"/>
    <parent link="gripper_base"/>
    <child link="gripper_right_spring_link"/>
    <axis xyz="1 0 0"/>
    <limit effort="176" lower="-2.9670591111111113" upper="2.9670591111111113" velocity="1.919861777777778"/>
  </joint>
  <link name="gripper_right_spring_link">
    <inertial>
      <mass value="0.1"/>
      <origin rpy="-0.7068 0 0" xyz="0 0.018 0.018"/>
      <inertia ixx="0.038541666666666675" ixy="0" ixz="0" iyy="0.04854166666666667" iyz="0" izz="0.016666666666666666"/>
    </inertial>
    <visual>
      <geometry>
        <mesh filename="package://robotiq_2f_model/meshes/2f85/visual/spring_link.obj" scale="0.001 0.001 0.001"/>
      </geometry>
    </visual>
    <collision>
      <geometry>
        <mesh filename="package://robotiq_2f_model/meshes/2f85/collision/spring_link.stl" scale="0.001 0.001 0.001"/>
      </geometry>
    </collision>
  </link>
  <!-- left finger -->
  <joint name="gripper_left_driver_joint" type="revolute">
    <origin rpy="0 0 3.141592653589793" xyz="0 -0.0306011 0.054904"/>
    <parent link="gripper_base"/>
    <child link="gripper_left_driver"/>
    <axis xyz="1 0 0"/>
    <limit effort="176" lower="0.0" upper="0.8726644444444445" velocity="1.919861777777778"/>
  </joint>
  <link name="gripper_left_driver">
    <inertial>
      <mass value="0.1"/>
      <origin rpy="0 0 0" xyz="0 0.02 0"/>
      <inertia ixx="0.016666666666666666" ixy="0" ixz="0" iyy="0.006666666666666667" iyz="0" izz="0.016666666666666666"/>
    </inertial>
    <visual>
      <geometry>
        <mesh filename="package://robotiq_2f_model/meshes/2f85/visual/driver.obj" scale="0.001 0.001 0.001"/>
      </geometry>
    </visual>
    <collision>
      <geometry>
        <mesh filename="package://robotiq_2f_model/meshes/2f85/collision/driver.stl" scale="0.001 0.001 0.001"/>
      </geometry>
    </collision>
  </link>
  <joint name="gripper_left_coupler_joint" type="revolute">
    <origin rpy="0 0 0" xyz="0 0.0315 -0.0041"/>
    <parent link="gripper_left_driver"/>
    <child link="gripper_left_coupler"/>
    <axis xyz="1 0 0"/>
    <limit effort="176" lower="-2.9670591111111113" upper="2.9670591111111113" velocity="1.919861777777778"/>
  </joint>
  <link name="gripper_left_coupler">
    <inertial>
      <mass value="0.1"/>
      <origin rpy="-1.7 0 0" xyz="0 0.0 0.025"/>
      <inertia ixx="0.038541666666666675" ixy="0" ixz="0" iyy="0.010833333333333334" iyz="0" izz="0.04270833333333334"/>
    </inertial>
    <visual>
      <geometry>
        <mesh filename="package://robotiq_2f_model/meshes/2f85/visual/coupler.obj" scale="0.001 0.001 0.001"/>
      </geometry>
    </visual>
    <collision>
      <geometry>
        <mesh filename="package://robotiq_2f_model/meshes/2f85/collision/coupler.stl" scale="0.001 0.001 0.001"/>
      </geometry>
    </collision>
  </link>
  <joint name="gripper_left_follower_joint" type="revolute">
    <origin rpy="0 0 0" xyz="0 0.0061 0.0471"/>
    <parent link="gripper_left_coupler"/>
    <child link="gripper_left_follower"/>
    <axis xyz="1 0 0"/>
    <limit effort="176" lower="-2.9670591111111113" upper="2.9670591111111113" velocity="1.919861777777778"/>
  </joint>
  <link name="gripper_left_follower">
    <inertial>
      <mass value="0.1"/>
      <origin xyz="0 -0.018 0.022"/>
      <inertia ixx="0.021075" ixy="0" ixz="0" iyy="0.022533333333333336" iyz="0" izz="0.005208333333333333"/>
    </inertial>
    <visual>
      <geometry>
        <mesh filename="package://robotiq_2f_model/meshes/2f85/visual/follower.obj" scale="0.001 0.001 0.001"/>
      </geometry>
    </visual>
    <collision>
      <geometry>
        <mesh filename="package://robotiq_2f_model/meshes/2f85/collision/follower.stl" scale="0.001 0.001 0.001"/>
      </geometry>
    </collision>
  </link>
  <joint name="gripper_left_pad_joint" type="fixed">
    <parent link="gripper_left_follower"/>
    <child link="gripper_left_pad"/>
  </joint>
  <link name="gripper_left_pad">
    <inertial>
      <mass value="0.1"/>
      <origin xyz="0 -0.022 0.031"/>
      <inertia ixx="0.011333333333333332" ixy="0" ixz="0" iyy="0.014133333333333331" iyz="0" izz="0.0038666666666666663"/>
    </inertial>
    <visual>
      <geometry>
        <mesh filename="package://robotiq_2f_model/meshes/2f85/visual/pad.obj" scale="0.001 0.001 0.001"/>
      </geometry>
    </visual>
    <collision>
      <geometry>
        <mesh filename="package://robotiq_2f_model/meshes/2f85/collision/pad.stl" scale="0.001 0.001 0.001"/>
      </geometry>
    </collision>
  </link>
  <joint name="gripper_left_spring_link_joint" type="revolute">
    <origin rpy="0 0 3.141592653589793" xyz="0 -0.012 0.0614"/>
    <parent link="gripper_base"/>
    <child link="gripper_left_spring_link"/>
    <axis xyz="1 0 0"/>
    <limit effort="176" lower="-2.9670591111111113" upper="2.9670591111111113" velocity="1.919861777777778"/>
  </joint>
  <link name="gripper_left_spring_link">
    <inertial>
      <mass value="0.1"/>
      <origin rpy="-0.7068 0 0" xyz="0 0.018 0.018"/>
      <inertia ixx="0.038541666666666675" ixy="0" ixz="0" iyy="0.04854166666666667" iyz="0" izz="0.016666666666666666"/>
    </inertial>
    <visual>
      <geometry>
        <mesh filename="package://robotiq_2f_model/meshes/2f85/visual/spring_link.obj" scale="0.001 0.001 0.001"/>
      </geometry>
    </visual>
    <collision>
      <geometry>
        <mesh filename="package://robotiq_2f_model/meshes/2f85/collision/spring_link.stl" scale="0.001 0.001 0.001"/>
      </geometry>
    </collision>
  </link>
</robot>

